Workbook

Sheet LEEME
A1: KJA | GANTT Y SPRINTS MENSUALES
A4: Periodo | B4: Antecedente: 28/08/2026. Sprint 1: septiembre; Sprint 2: octubre; Sprint 3: noviembre; Sprint 4: diciembre de 2026.
A5: Corte histórico | B5: 22/09/2026. El despliegue inicial del 28/08 consta en docs/dashboard-base.md y en el commit d189536.
A6: Cómo leer el Gantt | B6: R = día con registro Git; D = despliegue documentado; L = documento local; P = día propuesto. Los colores agrupan H.U.; las letras distinguen evidencia y planificación.
A7: Duración | B7: Número de días marcados por tarea. En el histórico son días con evidencia, no esfuerzo ni dedicación continua. No sumar estas duraciones como duración total del proyecto.
A8: Responsables | B8: Histórico: nombres tal como aparecen en Git, sin atribuirles responsabilidad contractual. Propuestas: roles pendientes de asignación nominal.
A9: Historias de usuario | B9: HU-G01–HU-G12 son agrupaciones propuestas para este cronograma; no sustituyen H.U. aprobadas ni prueban que existieran en esas fechas.
A10: Todas las áreas | B10: Se incluyen las 10 áreas de las semillas SQL. Dirección y Sistemas participan transversalmente. Confirmar catálogo vigente: no se consultó la base remota.
A11: Calendario | B11: Propuestas de lunes a viernes; exclusiones iniciales por confirmar: 08/10, 08/12, 09/12 y 25/12. Editar Laborable en CALENDARIO. El histórico conserva registros de fines de semana.
A12: Actualizar | B12: Editar filas existentes en TAREAS: fechas, responsable, tarea, naturaleza y evidencias. La duración y las barras se recalculan. Editar CALENDARIO modifica días propuestos.
A13: Cambiar de sprint o agregar filas | B13: Las pestañas contienen la selección inicial por mes. Al agregar una tarea o cambiarla de mes, actualizar también su fila y fórmulas en la pestaña de destino.
A14: Límite del plan | B14: Las fechas futuras son propuestas; no son trabajo terminado ni autorización para desplegar o publicar. El plan usa un frente principal de Sistemas y debe ajustarse a la capacidad real.
A15: Evidencia | B15: TAREAS conserva fuente/commit, fechas de registro, RF relacionados, dependencias y criterio de salida. Registro Git no prueba un despliegue ni una prueba funcional aprobada.
A17: Sprint | B17: Mes | C17: Objetivo | D17: Tareas | E17: Registros | F17: Propuestas | G17: Inicio | H17: Fin
A18: Antecedente | B18: Agosto | C18: Puesta en marcha | D18: =COUNTIF(TAREAS!$B$5:$B$64,A18) -> 3 | E18: =COUNTIFS(TAREAS!$B$5:$B$64,A18,TAREAS!$I$5:$I$64,"<>Propuesta") -> 3 | F18: =COUNTIFS(TAREAS!$B$5:$B$64,A18,TAREAS!$I$5:$I$64,"Propuesta") -> 0 | G18: 46262 | H18: 46265
A19: Sprint 1 | B19: Septiembre | C19: Consolidar y documentar | D19: =COUNTIF(TAREAS!$B$5:$B$64,A19) -> 29 | E19: =COUNTIFS(TAREAS!$B$5:$B$64,A19,TAREAS!$I$5:$I$64,"<>Propuesta") -> 25 | F19: =COUNTIFS(TAREAS!$B$5:$B$64,A19,TAREAS!$I$5:$I$64,"Propuesta") -> 4 | G19: 46266 | H19: 46295
A20: Sprint 2 | B20: Octubre | C20: Actualizar las diez áreas | D20: =COUNTIF(TAREAS!$B$5:$B$64,A20) -> 11 | E20: =COUNTIFS(TAREAS!$B$5:$B$64,A20,TAREAS!$I$5:$I$64,"<>Propuesta") -> 0 | F20: =COUNTIFS(TAREAS!$B$5:$B$64,A20,TAREAS!$I$5:$I$64,"Propuesta") -> 11 | G20: 46296 | H20: 46326
A21: Sprint 3 | B21: Noviembre | C21: Implementar mejoras priorizadas | D21: =COUNTIF(TAREAS!$B$5:$B$64,A21) -> 8 | E21: =COUNTIFS(TAREAS!$B$5:$B$64,A21,TAREAS!$I$5:$I$64,"<>Propuesta") -> 0 | F21: =COUNTIFS(TAREAS!$B$5:$B$64,A21,TAREAS!$I$5:$I$64,"Propuesta") -> 8 | G21: 46327 | H21: 46356
A22: Sprint 4 | B22: Diciembre | C22: Validar, capacitar y cerrar | D22: =COUNTIF(TAREAS!$B$5:$B$64,A22) -> 9 | E22: =COUNTIFS(TAREAS!$B$5:$B$64,A22,TAREAS!$I$5:$I$64,"<>Propuesta") -> 0 | F22: =COUNTIFS(TAREAS!$B$5:$B$64,A22,TAREAS!$I$5:$I$64,"Propuesta") -> 9 | G22: 46357 | H22: 46387

Sheet ANTECEDENTE
A1: ANTECEDENTE · AGOSTO 2026 | GANTT
A3: Puesta en marcha · Corte histórico: 22/09/2026 · Fechas futuras propuestas
A4: R registro Git · D despliegue documentado · L documento local · P propuesta | Duración = días marcados, no horas de esfuerzo
A5: Editar TAREAS para actualizar fechas y contenido. HU-G son agrupaciones propuestas; responsables futuros pendientes de confirmación.
A7: Historia de usuario propuesta | B7: Tarea / entregable | C7: Responsable / autor | D7: Días | E7: 46262 | F7: 46263 | G7: 46264 | H7: 46265
E8: V | F8: S | G8: D | H8: L
A9: =TAREAS!C5 -> HU-G01 · Como colaborador, quiero acceder al portal y consultar mi asistencia. | B9: =TAREAS!A5&" · "&TAREAS!D5 -> T-001 · Acceso, permisos e integración inicial del dashboard | C9: =TAREAS!F5 -> yeiserDev | D9: =COUNTIF(E9:H9,"R")+COUNTIF(E9:H9,"D")+COUNTIF(E9:H9,"L")+COUNTIF(E9:H9,"P") -> 1 | E9: =IF(TAREAS!$I$5="Propuesta",IF(AND(E$7>=TAREAS!$G$5,E$7<=TAREAS!$H$5,CALENDARIO!$C$5=1),"P",""),IF(ISNUMBER(SEARCH(TEXT(E$7,"yyyy-mm-dd"),TAREAS!$J$5)),IF(TAREAS!$I$5="Registro Git","R",IF(TAREAS!$I$5="Despliegue documentado","D","L")),"")) -> R | F9: =IF(TAREAS!$I$5="Propuesta",IF(AND(F$7>=TAREAS!$G$5,F$7<=TAREAS!$H$5,CALENDARIO!$C$6=1),"P",""),IF(ISNUMBER(SEARCH(TEXT(F$7,"yyyy-mm-dd"),TAREAS!$J$5)),IF(TAREAS!$I$5="Registro Git","R",IF(TAREAS!$I$5="Despliegue documentado","D","L")),"")) | G9: =IF(TAREAS!$I$5="Propuesta",IF(AND(G$7>=TAREAS!$G$5,G$7<=TAREAS!$H$5,CALENDARIO!$C$7=1),"P",""),IF(ISNUMBER(SEARCH(TEXT(G$7,"yyyy-mm-dd"),TAREAS!$J$5)),IF(TAREAS!$I$5="Registro Git","R",IF(TAREAS!$I$5="Despliegue documentado","D","L")),"")) | H9: =IF(TAREAS!$I$5="Propuesta",IF(AND(H$7>=TAREAS!$G$5,H$7<=TAREAS!$H$5,CALENDARIO!$C$8=1),"P",""),IF(ISNUMBER(SEARCH(TEXT(H$7,"yyyy-mm-dd"),TAREAS!$J$5)),IF(TAREAS!$I$5="Registro Git","R",IF(TAREAS!$I$5="Despliegue documentado","D","L")),""))
A10: =TAREAS!C6 -> HU-G01 · Como colaborador, quiero acceder al portal y consultar mi asistencia. | B10: =TAREAS!A6&" · "&TAREAS!D6 -> T-002 · Hito: despliegue inicial del portal documentado | C10: =TAREAS!F6 -> Por confirmar | D10: =COUNTIF(E10:H10,"R")+COUNTIF(E10:H10,"D")+COUNTIF(E10:H10,"L")+COUNTIF(E10:H10,"P") -> 1 | E10: =IF(TAREAS!$I$6="Propuesta",IF(AND(E$7>=TAREAS!$G$6,E$7<=TAREAS!$H$6,CALENDARIO!$C$5=1),"P",""),IF(ISNUMBER(SEARCH(TEXT(E$7,"yyyy-mm-dd"),TAREAS!$J$6)),IF(TAREAS!$I$6="Registro Git","R",IF(TAREAS!$I$6="Despliegue documentado","D","L")),"")) -> D | F10: =IF(TAREAS!$I$6="Propuesta",IF(AND(F$7>=TAREAS!$G$6,F$7<=TAREAS!$H$6,CALENDARIO!$C$6=1),"P",""),IF(ISNUMBER(SEARCH(TEXT(F$7,"yyyy-mm-dd"),TAREAS!$J$6)),IF(TAREAS!$I$6="Registro Git","R",IF(TAREAS!$I$6="Despliegue documentado","D","L")),"")) | G10: =IF(TAREAS!$I$6="Propuesta",IF(AND(G$7>=TAREAS!$G$6,G$7<=TAREAS!$H$6,CALENDARIO!$C$7=1),"P",""),IF(ISNUMBER(SEARCH(TEXT(G$7,"yyyy-mm-dd"),TAREAS!$J$6)),IF(TAREAS!$I$6="Registro Git","R",IF(TAREAS!$I$6="Despliegue documentado","D","L")),"")) | H10: =IF(TAREAS!$I$6="Propuesta",IF(AND(H$7>=TAREAS!$G$6,H$7<=TAREAS!$H$6,CALENDARIO!$C$8=1),"P",""),IF(ISNUMBER(SEARCH(TEXT(H$7,"yyyy-mm-dd"),TAREAS!$J$6)),IF(TAREAS!$I$6="Registro Git","R",IF(TAREAS!$I$6="Despliegue documentado","D","L")),""))
A11: =TAREAS!C7 -> HU-G03 · Como colaborador, quiero gestionar mi perfil y mis solicitudes. | B11: =TAREAS!A7&" · "&TAREAS!D7 -> T-003 · Fotografía privada, avatar y mejora del ingreso | C11: =TAREAS!F7 -> yeiserDev | D11: =COUNTIF(E11:H11,"R")+COUNTIF(E11:H11,"D")+COUNTIF(E11:H11,"L")+COUNTIF(E11:H11,"P") -> 1 | E11: =IF(TAREAS!$I$7="Propuesta",IF(AND(E$7>=TAREAS!$G$7,E$7<=TAREAS!$H$7,CALENDARIO!$C$5=1),"P",""),IF(ISNUMBER(SEARCH(TEXT(E$7,"yyyy-mm-dd"),TAREAS!$J$7)),IF(TAREAS!$I$7="Registro Git","R",IF(TAREAS!$I$7="Despliegue documentado","D","L")),"")) -> R | F11: =IF(TAREAS!$I$7="Propuesta",IF(AND(F$7>=TAREAS!$G$7,F$7<=TAREAS!$H$7,CALENDARIO!$C$6=1),"P",""),IF(ISNUMBER(SEARCH(TEXT(F$7,"yyyy-mm-dd"),TAREAS!$J$7)),IF(TAREAS!$I$7="Registro Git","R",IF(TAREAS!$I$7="Despliegue documentado","D","L")),"")) | G11: =IF(TAREAS!$I$7="Propuesta",IF(AND(G$7>=TAREAS!$G$7,G$7<=TAREAS!$H$7,CALENDARIO!$C$7=1),"P",""),IF(ISNUMBER(SEARCH(TEXT(G$7,"yyyy-mm-dd"),TAREAS!$J$7)),IF(TAREAS!$I$7="Registro Git","R",IF(TAREAS!$I$7="Despliegue documentado","D","L")),"")) | H11: =IF(TAREAS!$I$7="Propuesta",IF(AND(H$7>=TAREAS!$G$7,H$7<=TAREAS!$H$7,CALENDARIO!$C$8=1),"P",""),IF(ISNUMBER(SEARCH(TEXT(H$7,"yyyy-mm-dd"),TAREAS!$J$7)),IF(TAREAS!$I$7="Registro Git","R",IF(TAREAS!$I$7="Despliegue documentado","D","L")),""))

Sheet SPRINT 1
A1: SPRINT 1 · SEPTIEMBRE 2026 | GANTT
A3: Consolidar y documentar · Corte histórico: 22/09/2026 · Fechas futuras propuestas
A4: R registro Git · D despliegue documentado · L documento local · P propuesta | Duración = días marcados, no horas de esfuerzo
A5: Editar TAREAS para actualizar fechas y contenido. HU-G son agrupaciones propuestas; responsables futuros pendientes de confirmación.
A7: Historia de usuario propuesta | B7: Tarea / entregable | C7: Responsable / autor | D7: Días | E7: 46266 | F7: 46267 | G7: 46268 | H7: 46269 | I7: 46270 | J7: 46271 | K7: 46272 | L7: 46273 | M7: 46274 | N7: 46275 | O7: 46276 | P7: 46277 | Q7: 46278 | R7: 46279 | S7: 46280 | T7: 46281 | U7: 46282 | V7: 46283 | W7: 46284 | X7: 46285 | Y7: 46286 | Z7: 46287 | AA7: 46288 | AB7: 46289 | AC7: 46290 | AD7: 46291 | AE7: 46292 | AF7: 46293 | AG7: 46294 | AH7: 46295
E8: M | F8: X | G8: J | H8: V | I8: S | J8: D | K8: L | L8: M | M8: X | N8: J | O8: V | P8: S | Q8: D | R8: L | S8: M | T8: X | U8: J | V8: V | W8: S | X8: D | Y8: L | Z8: M | AA8: X | AB8: J | AC8: V | AD8: S | AE8: D | AF8: L | AG8: M | AH8: X
A9: =TAREAS!C8 -> HU-G02 · Como colaborador, quiero registrar mi jornada según modalidad y ubicación. | B9: =TAREAS!A8&" · "&TAREAS!D8 -> T-004 · Marcado seguro, geocerca y mapa de oficina | C9: =TAREAS!F8 -> yeiserDev | D9: =COUNTIF(E9:AH9,"R")+COUNTIF(E9:AH9,"D")+COUNTIF(E9:AH9,"L")+COUNTIF(E9:AH9,"P") -> 1 | E9: =IF(TAREAS!$I$8="Propuesta",IF(AND(E$7>=TAREAS!$G$8,E$7<=TAREAS!$H$8,CALENDARIO!$C$9=1),"P",""),IF(ISNUMBER(SEARCH(TEXT(E$7,"yyyy-mm-dd"),TAREAS!$J$8)),IF(TAREAS!$I$8="Registro Git","R",IF(TAREAS!$I$8="Despliegue documentado","D","L")),"")) -> R | F9: =IF(TAREAS!$I$8="Propuesta",IF(AND(F$7>=TAREAS!$G$8,F$7<=TAREAS!$H$8,CALENDARIO!$C$10=1),"P",""),IF(ISNUMBER(SEARCH(TEXT(F$7,"yyyy-mm-dd"),TAREAS!$J$8)),IF(TAREAS!$I$8="Registro Git","R",IF(TAREAS!$I$8="Despliegue documentado","D","L")),"")) | G9: =IF(TAREAS!$I$8="Propuesta",IF(AND(G$7>=TAREAS!$G$8,G$7<=TAREAS!$H$8,CALENDARIO!$C$11=1),"P",""),IF(ISNUMBER(SEARCH(TEXT(G$7,"yyyy-mm-dd"),TAREAS!$J$8)),IF(TAREAS!$I$8="Registro Git","R",IF(TAREAS!$I$8="Despliegue documentado","D","L")),"")) | H9: =IF(TAREAS!$I$8="Propuesta",IF(AND(H$7>=TAREAS!$G$8,H$7<=TAREAS!$H$8,CALENDARIO!$C$12=1),"P",""),IF(ISNUMBER(SEARCH(TEXT(H$7,"yyyy-mm-dd"),TAREAS!$J$8)),IF(TAREAS!$I$8="Registro Git","R",IF(TAREAS!$I$8="Despliegue documentado","D","L")),"")) | I9: =IF(TAREAS!$I$8="Propuesta",IF(AND(I$7>=TAREAS!$G$8,I$7<=TAREAS!$H$8,CALENDARIO!$C$13=1),"P",""),IF(ISNUMBER(SEARCH(TEXT(I$7,"yyyy-mm-dd"),TAREAS!$J$8)),IF(TAREAS!$I$8="Registro Git","R",IF(TAREAS!$I$8="Despliegue documentado","D","L")),"")) | J9: =IF(TAREAS!$I$8="Propuesta",IF(AND(J$7>=TAREAS!$G$8,J$7<=TAREAS!$H$8,CALENDARIO!$C$14=1),"P",""),IF(ISNUMBER(SEARCH(TEXT(J$7,"yyyy-mm-dd"),TAREAS!$J$8)),IF(TAREAS!$I$8="Registro Git","R",IF(TAREAS!$I$8="Despliegue documentado","D","L")),"")) | K9: =IF(TAREAS!$I$8="Propuesta",IF(AND(K$7>=TAREAS!$G$8,K$7<=TAREAS!$H$8,CALENDARIO!$C$15=1),"P",""),IF(ISNUMBER(SEARCH(TEXT(K$7,"yyyy-mm-dd"),TAREAS!$J$8)),IF(TAREAS!$I$8="Registro Git","R",IF(TAREAS!$I$8="Despliegue documentado","D","L")),"")) | L9: =IF(TAREAS!$I$8="Propuesta",IF(AND(L$7>=TAREAS!$G$8,L$7<=TAREAS!$H$8,CALENDARIO!$C$16=1),"P",""),IF(ISNUMBER(SEARCH(TEXT(L$7,"yyyy-mm-dd"),TAREAS!$J$8)),IF(TAREAS!$I$8="Registro Git","R",IF(TAREAS!$I$8="Despliegue documentado","D","L")),"")) | M9: =IF(TAREAS!$I$8="Propuesta",IF(AND(M$7>=TAREAS!$G$8,M$7<=TAREAS!$H$8,CALENDARIO!$C$17=1),"P",""),IF(ISNUMBER(SEARCH(TEXT(M$7,"yyyy-mm-dd"),TAREAS!$J$8)),IF(TAREAS!$I$8="Registro Git","R",IF(TAREAS!$I$8="Despliegue documentado","D","L")),"")) | N9: =IF(TAREAS!$I$8="Propuesta",IF(AND(N$7>=TAREAS!$G$8,N$7<=TAREAS!$H$8,CALENDARIO!$C$18=1),"P",""),IF(ISNUMBER(SEARCH(TEXT(N$7,"yyyy-mm-dd"),TAREAS!$J$8)),IF(TAREAS!$I$8="Registro Git","R",IF(TAREAS!$I$8="Despliegue documentado","D","L")),"")) | O9: =IF(TAREAS!$I$8="Propuesta",IF(AND(O$7>=TAREAS!$G$8,O$7<=TAREAS!$H$8,CALENDARIO!$C$19=1),"P",""),IF(ISNUMBER(SEARCH(TEXT(O$7,"yyyy-mm-dd"),TAREAS!$J$8)),IF(TAREAS!$I$8="Registro Git","R",IF(TAREAS!$I$8="Despliegue documentado","D","L")),"")) | P9: =IF(TAREAS!$I$8="Propuesta",IF(AND(P$7>=TAREAS!$G$8,P$7<=TAREAS!$H$8,CALENDARIO!$C$20=1),"P",""),IF(ISNUMBER(SEARCH(TEXT(P$7,"yyyy-mm-dd"),TAREAS!$J$8)),IF(TAREAS!$I$8="Registro Git","R",IF(TAREAS!$I$8="Despliegue documentado","D","L")),"")) | Q9: =IF(TAREAS!$I$8="Propuesta",IF(AND(Q$7>=TAREAS!$G$8,Q$7<=TAREAS!$H$8,CALENDARIO!$C$21=1),"P",""),IF(ISNUMBER(SEARCH(TEXT(Q$7,"yyyy-mm-dd"),TAREAS!$J$8)),IF(TAREAS!$I$8="Registro Git","R",IF(TAREAS!$I$8="Despliegue documentado","D","L")),"")) | R9: =IF(TAREAS!$I$8="Propuesta",IF(AND(R$7>=TAREAS!$G$8,R$7<=TAREAS!$H$8,CALENDARIO!$C$22=1),"P",""),IF(ISNUMBER(SEARCH(TEXT(R$7,"yyyy-mm-dd"),TAREAS!$J$8)),IF(TAREAS!$I$8="Registro Git","R",IF(TAREAS!$I$8="Despliegue documentado","D","L")),"")) | S9: =IF(TAREAS!$I$8="Propuesta",IF(AND(S$7>=TAREAS!$G$8,S$7<=TAREAS!$H$8,CALENDARIO!$C$23=1),"P",""),IF(ISNUMBER(SEARCH(TEXT(S$7,"yyyy-mm-dd"),TAREAS!$J$8)),IF(TAREAS!$I$8="Registro Git","R",IF(TAREAS!$I$8="Despliegue documentado","D","L")),"")) | T9: =IF(TAREAS!$I$8="Propuesta",IF(AND(T$7>=TAREAS!$G$8,T$7<=TAREAS!$H$8,CALENDARIO!$C$24=1),"P",""),IF(ISNUMBER(SEARCH(TEXT(T$7,"yyyy-mm-dd"),TAREAS!$J$8)),IF(TAREAS!$I$8="Registro Git","R",IF(TAREAS!$I$8="Despliegue documentado","D","L")),"")) | U9: =IF(TAREAS!$I$8="Propuesta",IF(AND(U$7>=TAREAS!$G$8,U$7<=TAREAS!$H$8,CALENDARIO!$C$25=1),"P",""),IF(ISNUMBER(SEARCH(TEXT(U$7,"yyyy-mm-dd"),TAREAS!$J$8)),IF(TAREAS!$I$8="Registro Git","R",IF(TAREAS!$I$8="Despliegue documentado","D","L")),"")) | V9: =IF(TAREAS!$I$8="Propuesta",IF(AND(V$7>=TAREAS!$G$8,V$7<=TAREAS!$H$8,CALENDARIO!$C$26=1),"P",""),IF(ISNUMBER(SEARCH(TEXT(V$7,"yyyy-mm-dd"),TAREAS!$J$8)),IF(TAREAS!$I$8="Registro Git","R",IF(TAREAS!$I$8="Despliegue documentado","D","L")),"")) | W9: =IF(TAREAS!$I$8="Propuesta",IF(AND(W$7>=TAREAS!$G$8,W$7<=TAREAS!$H$8,CALENDARIO!$C$27=1),"P",""),IF(ISNUMBER(SEARCH(TEXT(W$7,"yyyy-mm-dd"),TAREAS!$J$8)),IF(TAREAS!$I$8="Registro Git","R",IF(TAREAS!$I$8="Despliegue documentado","D","L")),"")) | X9: =IF(TAREAS!$I$8="Propuesta",IF(AND(X$7>=TAREAS!$G$8,X$7<=TAREAS!$H$8,CALENDARIO!$C$28=1),"P",""),IF(ISNUMBER(SEARCH(TEXT(X$7,"yyyy-mm-dd"),TAREAS!$J$8)),IF(TAREAS!$I$8="Registro Git","R",IF(TAREAS!$I$8="Despliegue documentado","D","L")),"")) | Y9: =IF(TAREAS!$I$8="Propuesta",IF(AND(Y$7>=TAREAS!$G$8,Y$7<=TAREAS!$H$8,CALENDARIO!$C$29=1),"P",""),IF(ISNUMBER(SEARCH(TEXT(Y$7,"yyyy-mm-dd"),TAREAS!$J$8)),IF(TAREAS!$I$8="Registro Git","R",IF(TAREAS!$I$8="Despliegue documentado","D","L")),"")) | Z9: =IF(TAREAS!$I$8="Propuesta",IF(AND(Z$7>=TAREAS!$G$8,Z$7<=TAREAS!$H$8,CALENDARIO!$C$30=1),"P",""),IF(ISNUMBER(SEARCH(TEXT(Z$7,"yyyy-mm-dd"),TAREAS!$J$8)),IF(TAREAS!$I$8="Registro Git","R",IF(TAREAS!$I$8="Despliegue documentado","D","L")),"")) | AA9: =IF(TAREAS!$I$8="Propuesta",IF(AND(AA$7>=TAREAS!$G$8,AA$7<=TAREAS!$H$8,CALENDARIO!$C$31=1),"P",""),IF(ISNUMBER(SEARCH(TEXT(AA$7,"yyyy-mm-dd"),TAREAS!$J$8)),IF(TAREAS!$I$8="Registro Git","R",IF(TAREAS!$I$8="Despliegue documentado","D","L")),"")) | AB9: =IF(TAREAS!$I$8="Propuesta",IF(AND(AB$7>=TAREAS!$G$8,AB$7<=TAREAS!$H$8,CALENDARIO!$C$32=1),"P",""),IF(ISNUMBER(SEARCH(TEXT(AB$7,"yyyy-mm-dd"),TAREAS!$J$8)),IF(TAREAS!$I$8="Registro Git","R",IF(TAREAS!$I$8="Despliegue documentado","D","L")),"")) | AC9: =IF(TAREAS!$I$8="Propuesta",IF(AND(AC$7>=TAREAS!$G$8,AC$7<=TAREAS!$H$8,CALENDARIO!$C$33=1),"P",""),IF(ISNUMBER(SEARCH(TEXT(AC$7,"yyyy-mm-dd"),TAREAS!$J$8)),IF(TAREAS!$I$8="Registro Git","R",IF(TAREAS!$I$8="Despliegue documentado","D","L")),"")) | AD9: =IF(TAREAS!$I$8="Propuesta",IF(AND(AD$7>=TAREAS!$G$8,AD$7<=TAREAS!$H$8,CALENDARIO!$C$34=1),"P",""),IF(ISNUMBER(SEARCH(TEXT(AD$7,"yyyy-mm-dd"),TAREAS!$J$8)),IF(TAREAS!$I$8="Registro Git","R",IF(TAREAS!$I$8="Despliegue documentado","D","L")),"")) | AE9: =IF(TAREAS!$I$8="Propuesta",IF(AND(AE$7>=TAREAS!$G$8,AE$7<=TAREAS!$H$8,CALENDARIO!$C$35=1),"P",""),IF(ISNUMBER(SEARCH(TEXT(AE$7,"yyyy-mm-dd"),TAREAS!$J$8)),IF(TAREAS!$I$8="Registro Git","R",IF(TAREAS!$I$8="Despliegue documentado","D","L")),"")) | AF9: =IF(TAREAS!$I$8="Propuesta",IF(AND(AF$7>=TAREAS!$G$8,AF$7<=TAREAS!$H$8,CALENDARIO!$C$36=1),"P",""),IF(ISNUMBER(SEARCH(TEXT(AF$7,"yyyy-mm-dd"),TAREAS!$J$8)),IF(TAREAS!$I$8="Registro Git","R",IF(TAREAS!$I$8="Despliegue documentado","D","L")),"")) | AG9: =IF(TAREAS!$I$8="Propuesta",IF(AND(AG$7>=TAREAS!$G$8,AG$7<=TAREAS!$H$8,CALENDARIO!$C$37=1),"P",""),IF(ISNUMBER(SEARCH(TEXT(AG$7,"yyyy-mm-dd"),TAREAS!$J$8)),IF(TAREAS!$I$8="Registro Git","R",IF(TAREAS!$I$8="Despliegue documentado","D","L")),"")) | AH9: =IF(TAREAS!$I$8="Propuesta",IF(AND(AH$7>=TAREAS!$G$8,AH$7<=TAREAS!$H$8,CALENDARIO!$C$38=1),"P",""),IF(ISNUMBER(SEARCH(TEXT(AH$7,"yyyy-mm-dd"),TAREAS!$J$8)),IF(TAREAS!$I$8="Registro Git","R",IF(TAREAS!$I$8="Despliegue documentado","D","L")),""))
A10: =TAREAS!C9 -> HU-G01 · Como colaborador, quiero acceder al portal y consultar mi asistencia. | B10: =TAREAS!A9&" · "&TAREAS!D9 -> T-005 · Acceso móvil y experiencia del panel administrativo | C10: =TAREAS!F9 -> jhony-abz, yeiserDev | D10: =COUNTIF(E10:AH10,"R")+COUNTIF(E10:AH10,"D")+COUNTIF(E10:AH10,"L")+COUNTIF(E10:AH10,"P") -> 2 | E10: =IF(TAREAS!$I$9="Propuesta",IF(AND(E$7>=TAREAS!$G$9,E$7<=TAREAS!$H$9,CALENDARIO!$C$9=1),"P",""),IF(ISNUMBER(SEARCH(TEXT(E$7,"yyyy-mm-dd"),TAREAS!$J$9)),IF(TAREAS!$I$9="Registro Git","R",IF(TAREAS!$I$9="Despliegue documentado","D","L")),"")) -> R | F10: =IF(TAREAS!$I$9="Propuesta",IF(AND(F$7>=TAREAS!$G$9,F$7<=TAREAS!$H$9,CALENDARIO!$C$10=1),"P",""),IF(ISNUMBER(SEARCH(TEXT(F$7,"yyyy-mm-dd"),TAREAS!$J$9)),IF(TAREAS!$I$9="Registro Git","R",IF(TAREAS!$I$9="Despliegue documentado","D","L")),"")) -> R | G10: =IF(TAREAS!$I$9="Propuesta",IF(AND(G$7>=TAREAS!$G$9,G$7<=TAREAS!$H$9,CALENDARIO!$C$11=1),"P",""),IF(ISNUMBER(SEARCH(TEXT(G$7,"yyyy-mm-dd"),TAREAS!$J$9)),IF(TAREAS!$I$9="Registro Git","R",IF(TAREAS!$I$9="Despliegue documentado","D","L")),"")) | H10: =IF(TAREAS!$I$9="Propuesta",IF(AND(H$7>=TAREAS!$G$9,H$7<=TAREAS!$H$9,CALENDARIO!$C$12=1),"P",""),IF(ISNUMBER(SEARCH(TEXT(H$7,"yyyy-mm-dd"),TAREAS!$J$9)),IF(TAREAS!$I$9="Registro Git","R",IF(TAREAS!$I$9="Despliegue documentado","D","L")),"")) | I10: =IF(TAREAS!$I$9="Propuesta",IF(AND(I$7>=TAREAS!$G$9,I$7<=TAREAS!$H$9,CALENDARIO!$C$13=1),"P",""),IF(ISNUMBER(SEARCH(TEXT(I$7,"yyyy-mm-dd"),TAREAS!$J$9)),IF(TAREAS!$I$9="Registro Git","R",IF(TAREAS!$I$9="Despliegue documentado","D","L")),"")) | J10: =IF(TAREAS!$I$9="Propuesta",IF(AND(J$7>=TAREAS!$G$9,J$7<=TAREAS!$H$9,CALENDARIO!$C$14=1),"P",""),IF(ISNUMBER(SEARCH(TEXT(J$7,"yyyy-mm-dd"),TAREAS!$J$9)),IF(TAREAS!$I$9="Registro Git","R",IF(TAREAS!$I$9="Despliegue documentado","D","L")),"")) | K10: =IF(TAREAS!$I$9="Propuesta",IF(AND(K$7>=TAREAS!$G$9,K$7<=TAREAS!$H$9,CALENDARIO!$C$15=1),"P",""),IF(ISNUMBER(SEARCH(TEXT(K$7,"yyyy-mm-dd"),TAREAS!$J$9)),IF(TAREAS!$I$9="Registro Git","R",IF(TAREAS!$I$9="Despliegue documentado","D","L")),"")) | L10: =IF(TAREAS!$I$9="Propuesta",IF(AND(L$7>=TAREAS!$G$9,L$7<=TAREAS!$H$9,CALENDARIO!$C$16=1),"P",""),IF(ISNUMBER(SEARCH(TEXT(L$7,"yyyy-mm-dd"),TAREAS!$J$9)),IF(TAREAS!$I$9="Registro Git","R",IF(TAREAS!$I$9="Despliegue documentado","D","L")),"")) | M10: =IF(TAREAS!$I$9="Propuesta",IF(AND(M$7>=TAREAS!$G$9,M$7<=TAREAS!$H$9,CALENDARIO!$C$17=1),"P",""),IF(ISNUMBER(SEARCH(TEXT(M$7,"yyyy-mm-dd"),TAREAS!$J$9)),IF(TAREAS!$I$9="Registro Git","R",IF(TAREAS!$I$9="Despliegue documentado","D","L")),"")) | N10: =IF(TAREAS!$I$9="Propuesta",IF(AND(N$7>=TAREAS!$G$9,N$7<=TAREAS!$H$9,CALENDARIO!$C$18=1),"P",""),IF(ISNUMBER(SEARCH(TEXT(N$7,"yyyy-mm-dd"),TAREAS!$J$9)),IF(TAREAS!$I$9="Registro Git","R",IF(TAREAS!$I$9="Despliegue documentado","D","L")),"")) | O10: =IF(TAREAS!$I$9="Propuesta",IF(AND(O$7>=TAREAS!$G$9,O$7<=TAREAS!$H$9,CALENDARIO!$C$19=1),"P",""),IF(ISNUMBER(SEARCH(TEXT(O$7,"yyyy-mm-dd"),TAREAS!$J$9)),IF(TAREAS!$I$9="Registro Git","R",IF(TAREAS!$I$9="Despliegue documentado","D","L")),"")) | P10: =IF(TAREAS!$I$9="Propuesta",IF(AND(P$7>=TAREAS!$G$9,P$7<=TAREAS!$H$9,CALENDARIO!$C$20=1),"P",""),IF(ISNUMBER(SEARCH(TEXT(P$7,"yyyy-mm-dd"),TAREAS!$J$9)),IF(TAREAS!$I$9="Registro Git","R",IF(TAREAS!$I$9="Despliegue documentado","D","L")),"")) | Q10: =IF(TAREAS!$I$9="Propuesta",IF(AND(Q$7>=TAREAS!$G$9,Q$7<=TAREAS!$H$9,CALENDARIO!$C$21=1),"P",""),IF(ISNUMBER(SEARCH(TEXT(Q$7,"yyyy-mm-dd"),TAREAS!$J$9)),IF(TAREAS!$I$9="Registro Git","R",IF(TAREAS!$I$9="Despliegue documentado","D","L")),"")) | R10: =IF(TAREAS!$I$9="Propuesta",IF(AND(R$7>=TAREAS!$G$9,R$7<=TAREAS!$H$9,CALENDARIO!$C$22=1),"P",""),IF(ISNUMBER(SEARCH(TEXT(R$7,"yyyy-mm-dd"),TAREAS!$J$9)),IF(TAREAS!$I$9="Registro Git","R",IF(TAREAS!$I$9="Despliegue documentado","D","L")),"")) | S10: =IF(TAREAS!$I$9="Propuesta",IF(AND(S$7>=TAREAS!$G$9,S$7<=TAREAS!$H$9,CALENDARIO!$C$23=1),"P",""),IF(ISNUMBER(SEARCH(TEXT(S$7,"yyyy-mm-dd"),TAREAS!$J$9)),IF(TAREAS!$I$9="Registro Git","R",IF(TAREAS!$I$9="Despliegue documentado","D","L")),"")) | T10: =IF(TAREAS!$I$9="Propuesta",IF(AND(T$7>=TAREAS!$G$9,T$7<=TAREAS!$H$9,CALENDARIO!$C$24=1),"P",""),IF(ISNUMBER(SEARCH(TEXT(T$7,"yyyy-mm-dd"),TAREAS!$J$9)),IF(TAREAS!$I$9="Registro Git","R",IF(TAREAS!$I$9="Despliegue documentado","D","L")),"")) | U10: =IF(TAREAS!$I$9="Propuesta",IF(AND(U$7>=TAREAS!$G$9,U$7<=TAREAS!$H$9,CALENDARIO!$C$25=1),"P",""),IF(ISNUMBER(SEARCH(TEXT(U$7,"yyyy-mm-dd"),TAREAS!$J$9)),IF(TAREAS!$I$9="Registro Git","R",IF(TAREAS!$I$9="Despliegue documentado","D","L")),"")) | V10: =IF(TAREAS!$I$9="Propuesta",IF(AND(V$7>=TAREAS!$G$9,V$7<=TAREAS!$H$9,CALENDARIO!$C$26=1),"P",""),IF(ISNUMBER(SEARCH(TEXT(V$7,"yyyy-mm-dd"),TAREAS!$J$9)),IF(TAREAS!$I$9="Registro Git","R",IF(TAREAS!$I$9="Despliegue documentado","D","L")),"")) | W10: =IF(TAREAS!$I$9="Propuesta",IF(AND(W$7>=TAREAS!$G$9,W$7<=TAREAS!$H$9,CALENDARIO!$C$27=1),"P",""),IF(ISNUMBER(SEARCH(TEXT(W$7,"yyyy-mm-dd"),TAREAS!$J$9)),IF(TAREAS!$I$9="Registro Git","R",IF(TAREAS!$I$9="Despliegue documentado","D","L")),"")) | X10: =IF(TAREAS!$I$9="Propuesta",IF(AND(X$7>=TAREAS!$G$9,X$7<=TAREAS!$H$9,CALENDARIO!$C$28=1),"P",""),IF(ISNUMBER(SEARCH(TEXT(X$7,"yyyy-mm-dd"),TAREAS!$J$9)),IF(TAREAS!$I$9="Registro Git","R",IF(TAREAS!$I$9="Despliegue documentado","D","L")),"")) | Y10: =IF(TAREAS!$I$9="Propuesta",IF(AND(Y$7>=TAREAS!$G$9,Y$7<=TAREAS!$H$9,CALENDARIO!$C$29=1),"P",""),IF(ISNUMBER(SEARCH(TEXT(Y$7,"yyyy-mm-dd"),TAREAS!$J$9)),IF(TAREAS!$I$9="Registro Git","R",IF(TAREAS!$I$9="Despliegue documentado","D","L")),"")) | Z10: =IF(TAREAS!$I$9="Propuesta",IF(AND(Z$7>=TAREAS!$G$9,Z$7<=TAREAS!$H$9,CALENDARIO!$C$30=1),"P",""),IF(ISNUMBER(SEARCH(TEXT(Z$7,"yyyy-mm-dd"),TAREAS!$J$9)),IF(TAREAS!$I$9="Registro Git","R",IF(TAREAS!$I$9="Despliegue documentado","D","L")),"")) | AA10: =IF(TAREAS!$I$9="Propuesta",IF(AND(AA$7>=TAREAS!$G$9,AA$7<=TAREAS!$H$9,CALENDARIO!$C$31=1),"P",""),IF(ISNUMBER(SEARCH(TEXT(AA$7,"yyyy-mm-dd"),TAREAS!$J$9)),IF(TAREAS!$I$9="Registro Git","R",IF(TAREAS!$I$9="Despliegue documentado","D","L")),"")) | AB10: =IF(TAREAS!$I$9="Propuesta",IF(AND(AB$7>=TAREAS!$G$9,AB$7<=TAREAS!$H$9,CALENDARIO!$C$32=1),"P",""),IF(ISNUMBER(SEARCH(TEXT(AB$7,"yyyy-mm-dd"),TAREAS!$J$9)),IF(TAREAS!$I$9="Registro Git","R",IF(TAREAS!$I$9="Despliegue documentado","D","L")),"")) | AC10: =IF(TAREAS!$I$9="Propuesta",IF(AND(AC$7>=TAREAS!$G$9,AC$7<=TAREAS!$H$9,CALENDARIO!$C$33=1),"P",""),IF(ISNUMBER(SEARCH(TEXT(AC$7,"yyyy-mm-dd"),TAREAS!$J$9)),IF(TAREAS!$I$9="Registro Git","R",IF(TAREAS!$I$9="Despliegue documentado","D","L")),"")) | AD10: =IF(TAREAS!$I$9="Propuesta",IF(AND(AD$7>=TAREAS!$G$9,AD$7<=TAREAS!$H$9,CALENDARIO!$C$34=1),"P",""),IF(ISNUMBER(SEARCH(TEXT(AD$7,"yyyy-mm-dd"),TAREAS!$J$9)),IF(TAREAS!$I$9="Registro Git","R",IF(TAREAS!$I$9="Despliegue documentado","D","L")),"")) | AE10: =IF(TAREAS!$I$9="Propuesta",IF(AND(AE$7>=TAREAS!$G$9,AE$7<=TAREAS!$H$9,CALENDARIO!$C$35=1),"P",""),IF(ISNUMBER(SEARCH(TEXT(AE$7,"yyyy-mm-dd"),TAREAS!$J$9)),IF(TAREAS!$I$9="Registro Git","R",IF(TAREAS!$I$9="Despliegue documentado","D","L")),"")) | AF10: =IF(TAREAS!$I$9="Propuesta",IF(AND(AF$7>=TAREAS!$G$9,AF$7<=TAREAS!$H$9,CALENDARIO!$C$36=1),"P",""),IF(ISNUMBER(SEARCH(TEXT(AF$7,"yyyy-mm-dd"),TAREAS!$J$9)),IF(TAREAS!$I$9="Registro Git","R",IF(TAREAS!$I$9="Despliegue documentado","D","L")),"")) | AG10: =IF(TAREAS!$I$9="Propuesta",IF(AND(AG$7>=TAREAS!$G$9,AG$7<=TAREAS!$H$9,CALENDARIO!$C$37=1),"P",""),IF(ISNUMBER(SEARCH(TEXT(AG$7,"yyyy-mm-dd"),TAREAS!$J$9)),IF(TAREAS!$I$9="Registro Git","R",IF(TAREAS!$I$9="Despliegue documentado","D","L")),"")) | AH10: =IF(TAREAS!$I$9="Propuesta",IF(AND(AH$7>=TAREAS!$G$9,AH$7<=TAREAS!$H$9,CALENDARIO!$C$38=1),"P",""),IF(ISNUMBER(SEARCH(TEXT(AH$7,"yyyy-mm-dd"),TAREAS!$J$9)),IF(TAREAS!$I$9="Registro Git","R",IF(TAREAS!$I$9="Despliegue documentado","D","L")),""))
A11: =TAREAS!C10 -> HU-G03 · Como colaborador, quiero gestionar mi perfil y mis solicitudes. | B11: =TAREAS!A10&" · "&TAREAS!D10 -> T-006 · Solicitudes personales, fotos y días libres | C11: =TAREAS!F10 -> yeiserDev | D11: =COUNTIF(E11:AH11,"R")+COUNTIF(E11:AH11,"D")+COUNTIF(E11:AH11,"L")+COUNTIF(E11:AH11,"P") -> 1 | E11: =IF(TAREAS!$I$10="Propuesta",IF(AND(E$7>=TAREAS!$G$10,E$7<=TAREAS!$H$10,CALENDARIO!$C$9=1),"P",""),IF(ISNUMBER(SEARCH(TEXT(E$7,"yyyy-mm-dd"),TAREAS!$J$10)),IF(TAREAS!$I$10="Registro Git","R",IF(TAREAS!$I$10="Despliegue documentado","D","L")),"")) | F11: =IF(TAREAS!$I$10="Propuesta",IF(AND(F$7>=TAREAS!$G$10,F$7<=TAREAS!$H$10,CALENDARIO!$C$10=1),"P",""),IF(ISNUMBER(SEARCH(TEXT(F$7,"yyyy-mm-dd"),TAREAS!$J$10)),IF(TAREAS!$I$10="Registro Git","R",IF(TAREAS!$I$10="Despliegue documentado","D","L")),"")) | G11: =IF(TAREAS!$I$10="Propuesta",IF(AND(G$7>=TAREAS!$G$10,G$7<=TAREAS!$H$10,CALENDARIO!$C$11=1),"P",""),IF(ISNUMBER(SEARCH(TEXT(G$7,"yyyy-mm-dd"),TAREAS!$J$10)),IF(TAREAS!$I$10="Registro Git","R",IF(TAREAS!$I$10="Despliegue documentado","D","L")),"")) -> R | H11: =IF(TAREAS!$I$10="Propuesta",IF(AND(H$7>=TAREAS!$G$10,H$7<=TAREAS!$H$10,CALENDARIO!$C$12=1),"P",""),IF(ISNUMBER(SEARCH(TEXT(H$7,"yyyy-mm-dd"),TAREAS!$J$10)),IF(TAREAS!$I$10="Registro Git","R",IF(TAREAS!$I$10="Despliegue documentado","D","L")),"")) | I11: =IF(TAREAS!$I$10="Propuesta",IF(AND(I$7>=TAREAS!$G$10,I$7<=TAREAS!$H$10,CALENDARIO!$C$13=1),"P",""),IF(ISNUMBER(SEARCH(TEXT(I$7,"yyyy-mm-dd"),TAREAS!$J$10)),IF(TAREAS!$I$10="Registro Git","R",IF(TAREAS!$I$10="Despliegue documentado","D","L")),"")) | J11: =IF(TAREAS!$I$10="Propuesta",IF(AND(J$7>=TAREAS!$G$10,J$7<=TAREAS!$H$10,CALENDARIO!$C$14=1),"P",""),IF(ISNUMBER(SEARCH(TEXT(J$7,"yyyy-mm-dd"),TAREAS!$J$10)),IF(TAREAS!$I$10="Registro Git","R",IF(TAREAS!$I$10="Despliegue documentado","D","L")),"")) | K11: =IF(TAREAS!$I$10="Propuesta",IF(AND(K$7>=TAREAS!$G$10,K$7<=TAREAS!$H$10,CALENDARIO!$C$15=1),"P",""),IF(ISNUMBER(SEARCH(TEXT(K$7,"yyyy-mm-dd"),TAREAS!$J$10)),IF(TAREAS!$I$10="Registro Git","R",IF(TAREAS!$I$10="Despliegue documentado","D","L")),"")) | L11: =IF(TAREAS!$I$10="Propuesta",IF(AND(L$7>=TAREAS!$G$10,L$7<=TAREAS!$H$10,CALENDARIO!$C$16=1),"P",""),IF(ISNUMBER(SEARCH(TEXT(L$7,"yyyy-mm-dd"),TAREAS!$J$10)),IF(TAREAS!$I$10="Registro Git","R",IF(TAREAS!$I$10="Despliegue documentado","D","L")),"")) | M11: =IF(TAREAS!$I$10="Propuesta",IF(AND(M$7>=TAREAS!$G$10,M$7<=TAREAS!$H$10,CALENDARIO!$C$17=1),"P",""),IF(ISNUMBER(SEARCH(TEXT(M$7,"yyyy-mm-dd"),TAREAS!$J$10)),IF(TAREAS!$I$10="Registro Git","R",IF(TAREAS!$I$10="Despliegue documentado","D","L")),"")) | N11: =IF(TAREAS!$I$10="Propuesta",IF(AND(N$7>=TAREAS!$G$10,N$7<=TAREAS!$H$10,CALENDARIO!$C$18=1),"P",""),IF(ISNUMBER(SEARCH(TEXT(N$7,"yyyy-mm-dd"),TAREAS!$J$10)),IF(TAREAS!$I$10="Registro Git","R",IF(TAREAS!$I$10="Despliegue documentado","D","L")),"")) | O11: =IF(TAREAS!$I$10="Propuesta",IF(AND(O$7>=TAREAS!$G$10,O$7<=TAREAS!$H$10,CALENDARIO!$C$19=1),"P",""),IF(ISNUMBER(SEARCH(TEXT(O$7,"yyyy-mm-dd"),TAREAS!$J$10)),IF(TAREAS!$I$10="Registro Git","R",IF(TAREAS!$I$10="Despliegue documentado","D","L")),"")) | P11: =IF(TAREAS!$I$10="Propuesta",IF(AND(P$7>=TAREAS!$G$10,P$7<=TAREAS!$H$10,CALENDARIO!$C$20=1),"P",""),IF(ISNUMBER(SEARCH(TEXT(P$7,"yyyy-mm-dd"),TAREAS!$J$10)),IF(TAREAS!$I$10="Registro Git","R",IF(TAREAS!$I$10="Despliegue documentado","D","L")),"")) | Q11: =IF(TAREAS!$I$10="Propuesta",IF(AND(Q$7>=TAREAS!$G$10,Q$7<=TAREAS!$H$10,CALENDARIO!$C$21=1),"P",""),IF(ISNUMBER(SEARCH(TEXT(Q$7,"yyyy-mm-dd"),TAREAS!$J$10)),IF(TAREAS!$I$10="Registro Git","R",IF(TAREAS!$I$10="Despliegue documentado","D","L")),"")) | R11: =IF(TAREAS!$I$10="Propuesta",IF(AND(R$7>=TAREAS!$G$10,R$7<=TAREAS!$H$10,CALENDARIO!$C$22=1),"P",""),IF(ISNUMBER(SEARCH(TEXT(R$7,"yyyy-mm-dd"),TAREAS!$J$10)),IF(TAREAS!$I$10="Registro Git","R",IF(TAREAS!$I$10="Despliegue documentado","D","L")),"")) | S11: =IF(TAREAS!$I$10="Propuesta",IF(AND(S$7>=TAREAS!$G$10,S$7<=TAREAS!$H$10,CALENDARIO!$C$23=1),"P",""),IF(ISNUMBER(SEARCH(TEXT(S$7,"yyyy-mm-dd"),TAREAS!$J$10)),IF(TAREAS!$I$10="Registro Git","R",IF(TAREAS!$I$10="Despliegue documentado","D","L")),"")) | T11: =IF(TAREAS!$I$10="Propuesta",IF(AND(T$7>=TAREAS!$G$10,T$7<=TAREAS!$H$10,CALENDARIO!$C$24=1),"P",""),IF(ISNUMBER(SEARCH(TEXT(T$7,"yyyy-mm-dd"),TAREAS!$J$10)),IF(TAREAS!$I$10="Registro Git","R",IF(TAREAS!$I$10="Despliegue documentado","D","L")),"")) | U11: =IF(TAREAS!$I$10="Propuesta",IF(AND(U$7>=TAREAS!$G$10,U$7<=TAREAS!$H$10,CALENDARIO!$C$25=1),"P",""),IF(ISNUMBER(SEARCH(TEXT(U$7,"yyyy-mm-dd"),TAREAS!$J$10)),IF(TAREAS!$I$10="Registro Git","R",IF(TAREAS!$I$10="Despliegue documentado","D","L")),"")) | V11: =IF(TAREAS!$I$10="Propuesta",IF(AND(V$7>=TAREAS!$G$10,V$7<=TAREAS!$H$10,CALENDARIO!$C$26=1),"P",""),IF(ISNUMBER(SEARCH(TEXT(V$7,"yyyy-mm-dd"),TAREAS!$J$10)),IF(TAREAS!$I$10="Registro Git","R",IF(TAREAS!$I$10="Despliegue documentado","D","L")),"")) | W11: =IF(TAREAS!$I$10="Propuesta",IF(AND(W$7>=TAREAS!$G$10,W$7<=TAREAS!$H$10,CALENDARIO!$C$27=1),"P",""),IF(ISNUMBER(SEARCH(TEXT(W$7,"yyyy-mm-dd"),TAREAS!$J$10)),IF(TAREAS!$I$10="Registro Git","R",IF(TAREAS!$I$10="Despliegue documentado","D","L")),"")) | X11: =IF(TAREAS!$I$10="Propuesta",IF(AND(X$7>=TAREAS!$G$10,X$7<=TAREAS!$H$10,CALENDARIO!$C$28=1),"P",""),IF(ISNUMBER(SEARCH(TEXT(X$7,"yyyy-mm-dd"),TAREAS!$J$10)),IF(TAREAS!$I$10="Registro Git","R",IF(TAREAS!$I$10="Despliegue documentado","D","L")),"")) | Y11: =IF(TAREAS!$I$10="Propuesta",IF(AND(Y$7>=TAREAS!$G$10,Y$7<=TAREAS!$H$10,CALENDARIO!$C$29=1),"P",""),IF(ISNUMBER(SEARCH(TEXT(Y$7,"yyyy-mm-dd"),TAREAS!$J$10)),IF(TAREAS!$I$10="Registro Git","R",IF(TAREAS!$I$10="Despliegue documentado","D","L")),"")) | Z11: =IF(TAREAS!$I$10="Propuesta",IF(AND(Z$7>=TAREAS!$G$10,Z$7<=TAREAS!$H$10,CALENDARIO!$C$30=1),"P",""),IF(ISNUMBER(SEARCH(TEXT(Z$7,"yyyy-mm-dd"),TAREAS!$J$10)),IF(TAREAS!$I$10="Registro Git","R",IF(TAREAS!$I$10="Despliegue documentado","D","L")),"")) | AA11: =IF(TAREAS!$I$10="Propuesta",IF(AND(AA$7>=TAREAS!$G$10,AA$7<=TAREAS!$H$10,CALENDARIO!$C$31=1),"P",""),IF(ISNUMBER(SEARCH(TEXT(AA$7,"yyyy-mm-dd"),TAREAS!$J$10)),IF(TAREAS!$I$10="Registro Git","R",IF(TAREAS!$I$10="Despliegue documentado","D","L")),"")) | AB11: =IF(TAREAS!$I$10="Propuesta",IF(AND(AB$7>=TAREAS!$G$10,AB$7<=TAREAS!$H$10,CALENDARIO!$C$32=1),"P",""),IF(ISNUMBER(SEARCH(TEXT(AB$7,"yyyy-mm-dd"),TAREAS!$J$10)),IF(TAREAS!$I$10="Registro Git","R",IF(TAREAS!$I$10="Despliegue documentado","D","L")),"")) | AC11: =IF(TAREAS!$I$10="Propuesta",IF(AND(AC$7>=TAREAS!$G$10,AC$7<=TAREAS!$H$10,CALENDARIO!$C$33=1),"P",""),IF(ISNUMBER(SEARCH(TEXT(AC$7,"yyyy-mm-dd"),TAREAS!$J$10)),IF(TAREAS!$I$10="Registro Git","R",IF(TAREAS!$I$10="Despliegue documentado","D","L")),"")) | AD11: =IF(TAREAS!$I$10="Propuesta",IF(AND(AD$7>=TAREAS!$G$10,AD$7<=TAREAS!$H$10,CALENDARIO!$C$34=1),"P",""),IF(ISNUMBER(SEARCH(TEXT(AD$7,"yyyy-mm-dd"),TAREAS!$J$10)),IF(TAREAS!$I$10="Registro Git","R",IF(TAREAS!$I$10="Despliegue documentado","D","L")),"")) | AE11: =IF(TAREAS!$I$10="Propuesta",IF(AND(AE$7>=TAREAS!$G$10,AE$7<=TAREAS!$H$10,CALENDARIO!$C$35=1),"P",""),IF(ISNUMBER(SEARCH(TEXT(AE$7,"yyyy-mm-dd"),TAREAS!$J$10)),IF(TAREAS!$I$10="Registro Git","R",IF(TAREAS!$I$10="Despliegue documentado","D","L")),"")) | AF11: =IF(TAREAS!$I$10="Propuesta",IF(AND(AF$7>=TAREAS!$G$10,AF$7<=TAREAS!$H$10,CALENDARIO!$C$36=1),"P",""),IF(ISNUMBER(SEARCH(TEXT(AF$7,"yyyy-mm-dd"),TAREAS!$J$10)),IF(TAREAS!$I$10="Registro Git","R",IF(TAREAS!$I$10="Despliegue documentado","D","L")),"")) | AG11: =IF(TAREAS!$I$10="Propuesta",IF(AND(AG$7>=TAREAS!$G$10,AG$7<=TAREAS!$H$10,CALENDARIO!$C$37=1),"P",""),IF(ISNUMBER(SEARCH(TEXT(AG$7,"yyyy-mm-dd"),TAREAS!$J$10)),IF(TAREAS!$I$10="Registro Git","R",IF(TAREAS!$I$10="Despliegue documentado","D","L")),"")) | AH11: =IF(TAREAS!$I$10="Propuesta",IF(AND(AH$7>=TAREAS!$G$10,AH$7<=TAREAS!$H$10,CALENDARIO!$C$38=1),"P",""),IF(ISNUMBER(SEARCH(TEXT(AH$7,"yyyy-mm-dd"),TAREAS!$J$10)),IF(TAREAS!$I$10="Registro Git","R",IF(TAREAS!$I$10="Despliegue documentado","D","L")),""))
A12: =TAREAS!C11 -> HU-G04 · Como colaborador, quiero entregar evidencias y conocer el cierre de mi jornada. | B12: =TAREAS!A11&" · "&TAREAS!D11 -> T-007 · Cierre diario con evidencias y salida | C12: =TAREAS!F11 -> yeiserDev | D12: =COUNTIF(E12:AH12,"R")+COUNTIF(E12:AH12,"D")+COUNTIF(E12:AH12,"L")+COUNTIF(E12:AH12,"P") -> 1 | E12: =IF(TAREAS!$I$11="Propuesta",IF(AND(E$7>=TAREAS!$G$11,E$7<=TAREAS!$H$11,CALENDARIO!$C$9=1),"P",""),IF(ISNUMBER(SEARCH(TEXT(E$7,"yyyy-mm-dd"),TAREAS!$J$11)),IF(TAREAS!$I$11="Registro Git","R",IF(TAREAS!$I$11="Despliegue documentado","D","L")),"")) | F12: =IF(TAREAS!$I$11="Propuesta",IF(AND(F$7>=TAREAS!$G$11,F$7<=TAREAS!$H$11,CALENDARIO!$C$10=1),"P",""),IF(ISNUMBER(SEARCH(TEXT(F$7,"yyyy-mm-dd"),TAREAS!$J$11)),IF(TAREAS!$I$11="Registro Git","R",IF(TAREAS!$I$11="Despliegue documentado","D","L")),"")) | G12: =IF(TAREAS!$I$11="Propuesta",IF(AND(G$7>=TAREAS!$G$11,G$7<=TAREAS!$H$11,CALENDARIO!$C$11=1),"P",""),IF(ISNUMBER(SEARCH(TEXT(G$7,"yyyy-mm-dd"),TAREAS!$J$11)),IF(TAREAS!$I$11="Registro Git","R",IF(TAREAS!$I$11="Despliegue documentado","D","L")),"")) | H12: =IF(TAREAS!$I$11="Propuesta",IF(AND(H$7>=TAREAS!$G$11,H$7<=TAREAS!$H$11,CALENDARIO!$C$12=1),"P",""),IF(ISNUMBER(SEARCH(TEXT(H$7,"yyyy-mm-dd"),TAREAS!$J$11)),IF(TAREAS!$I$11="Registro Git","R",IF(TAREAS!$I$11="Despliegue documentado","D","L")),"")) | I12: =IF(TAREAS!$I$11="Propuesta",IF(AND(I$7>=TAREAS!$G$11,I$7<=TAREAS!$H$11,CALENDARIO!$C$13=1),"P",""),IF(ISNUMBER(SEARCH(TEXT(I$7,"yyyy-mm-dd"),TAREAS!$J$11)),IF(TAREAS!$I$11="Registro Git","R",IF(TAREAS!$I$11="Despliegue documentado","D","L")),"")) | J12: =IF(TAREAS!$I$11="Propuesta",IF(AND(J$7>=TAREAS!$G$11,J$7<=TAREAS!$H$11,CALENDARIO!$C$14=1),"P",""),IF(ISNUMBER(SEARCH(TEXT(J$7,"yyyy-mm-dd"),TAREAS!$J$11)),IF(TAREAS!$I$11="Registro Git","R",IF(TAREAS!$I$11="Despliegue documentado","D","L")),"")) | K12: =IF(TAREAS!$I$11="Propuesta",IF(AND(K$7>=TAREAS!$G$11,K$7<=TAREAS!$H$11,CALENDARIO!$C$15=1),"P",""),IF(ISNUMBER(SEARCH(TEXT(K$7,"yyyy-mm-dd"),TAREAS!$J$11)),IF(TAREAS!$I$11="Registro Git","R",IF(TAREAS!$I$11="Despliegue documentado","D","L")),"")) -> R | L12: =IF(TAREAS!$I$11="Propuesta",IF(AND(L$7>=TAREAS!$G$11,L$7<=TAREAS!$H$11,CALENDARIO!$C$16=1),"P",""),IF(ISNUMBER(SEARCH(TEXT(L$7,"yyyy-mm-dd"),TAREAS!$J$11)),IF(TAREAS!$I$11="Registro Git","R",IF(TAREAS!$I$11="Despliegue documentado","D","L")),"")) | M12: =IF(TAREAS!$I$11="Propuesta",IF(AND(M$7>=TAREAS!$G$11,M$7<=TAREAS!$H$11,CALENDARIO!$C$17=1),"P",""),IF(ISNUMBER(SEARCH(TEXT(M$7,"yyyy-mm-dd"),TAREAS!$J$11)),IF(TAREAS!$I$11="Registro Git","R",IF(TAREAS!$I$11="Despliegue documentado","D","L")),"")) | N12: =IF(TAREAS!$I$11="Propuesta",IF(AND(N$7>=TAREAS!$G$11,N$7<=TAREAS!$H$11,CALENDARIO!$C$18=1),"P",""),IF(ISNUMBER(SEARCH(TEXT(N$7,"yyyy-mm-dd"),TAREAS!$J$11)),IF(TAREAS!$I$11="Registro Git","R",IF(TAREAS!$I$11="Despliegue documentado","D","L")),"")) | O12: =IF(TAREAS!$I$11="Propuesta",IF(AND(O$7>=TAREAS!$G$11,O$7<=TAREAS!$H$11,CALENDARIO!$C$19=1),"P",""),IF(ISNUMBER(SEARCH(TEXT(O$7,"yyyy-mm-dd"),TAREAS!$J$11)),IF(TAREAS!$I$11="Registro Git","R",IF(TAREAS!$I$11="Despliegue documentado","D","L")),"")) | P12: =IF(TAREAS!$I$11="Propuesta",IF(AND(P$7>=TAREAS!$G$11,P$7<=TAREAS!$H$11,CALENDARIO!$C$20=1),"P",""),IF(ISNUMBER(SEARCH(TEXT(P$7,"yyyy-mm-dd"),TAREAS!$J$11)),IF(TAREAS!$I$11="Registro Git","R",IF(TAREAS!$I$11="Despliegue documentado","D","L")),"")) | Q12: =IF(TAREAS!$I$11="Propuesta",IF(AND(Q$7>=TAREAS!$G$11,Q$7<=TAREAS!$H$11,CALENDARIO!$C$21=1),"P",""),IF(ISNUMBER(SEARCH(TEXT(Q$7,"yyyy-mm-dd"),TAREAS!$J$11)),IF(TAREAS!$I$11="Registro Git","R",IF(TAREAS!$I$11="Despliegue documentado","D","L")),"")) | R12: =IF(TAREAS!$I$11="Propuesta",IF(AND(R$7>=TAREAS!$G$11,R$7<=TAREAS!$H$11,CALENDARIO!$C$22=1),"P",""),IF(ISNUMBER(SEARCH(TEXT(R$7,"yyyy-mm-dd"),TAREAS!$J$11)),IF(TAREAS!$I$11="Registro Git","R",IF(TAREAS!$I$11="Despliegue documentado","D","L")),"")) | S12: =IF(TAREAS!$I$11="Propuesta",IF(AND(S$7>=TAREAS!$G$11,S$7<=TAREAS!$H$11,CALENDARIO!$C$23=1),"P",""),IF(ISNUMBER(SEARCH(TEXT(S$7,"yyyy-mm-dd"),TAREAS!$J$11)),IF(TAREAS!$I$11="Registro Git","R",IF(TAREAS!$I$11="Despliegue documentado","D","L")),"")) | T12: =IF(TAREAS!$I$11="Propuesta",IF(AND(T$7>=TAREAS!$G$11,T$7<=TAREAS!$H$11,CALENDARIO!$C$24=1),"P",""),IF(ISNUMBER(SEARCH(TEXT(T$7,"yyyy-mm-dd"),TAREAS!$J$11)),IF(TAREAS!$I$11="Registro Git","R",IF(TAREAS!$I$11="Despliegue documentado","D","L")),"")) | U12: =IF(TAREAS!$I$11="Propuesta",IF(AND(U$7>=TAREAS!$G$11,U$7<=TAREAS!$H$11,CALENDARIO!$C$25=1),"P",""),IF(ISNUMBER(SEARCH(TEXT(U$7,"yyyy-mm-dd"),TAREAS!$J$11)),IF(TAREAS!$I$11="Registro Git","R",IF(TAREAS!$I$11="Despliegue documentado","D","L")),"")) | V12: =IF(TAREAS!$I$11="Propuesta",IF(AND(V$7>=TAREAS!$G$11,V$7<=TAREAS!$H$11,CALENDARIO!$C$26=1),"P",""),IF(ISNUMBER(SEARCH(TEXT(V$7,"yyyy-mm-dd"),TAREAS!$J$11)),IF(TAREAS!$I$11="Registro Git","R",IF(TAREAS!$I$11="Despliegue documentado","D","L")),"")) | W12: =IF(TAREAS!$I$11="Propuesta",IF(AND(W$7>=TAREAS!$G$11,W$7<=TAREAS!$H$11,CALENDARIO!$C$27=1),"P",""),IF(ISNUMBER(SEARCH(TEXT(W$7,"yyyy-mm-dd"),TAREAS!$J$11)),IF(TAREAS!$I$11="Registro Git","R",IF(TAREAS!$I$11="Despliegue documentado","D","L")),"")) | X12: =IF(TAREAS!$I$11="Propuesta",IF(AND(X$7>=TAREAS!$G$11,X$7<=TAREAS!$H$11,CALENDARIO!$C$28=1),"P",""),IF(ISNUMBER(SEARCH(TEXT(X$7,"yyyy-mm-dd"),TAREAS!$J$11)),IF(TAREAS!$I$11="Registro Git","R",IF(TAREAS!$I$11="Despliegue documentado","D","L")),"")) | Y12: =IF(TAREAS!$I$11="Propuesta",IF(AND(Y$7>=TAREAS!$G$11,Y$7<=TAREAS!$H$11,CALENDARIO!$C$29=1),"P",""),IF(ISNUMBER(SEARCH(TEXT(Y$7,"yyyy-mm-dd"),TAREAS!$J$11)),IF(TAREAS!$I$11="Registro Git","R",IF(TAREAS!$I$11="Despliegue documentado","D","L")),"")) | Z12: =IF(TAREAS!$I$11="Propuesta",IF(AND(Z$7>=TAREAS!$G$11,Z$7<=TAREAS!$H$11,CALENDARIO!$C$30=1),"P",""),IF(ISNUMBER(SEARCH(TEXT(Z$7,"yyyy-mm-dd"),TAREAS!$J$11)),IF(TAREAS!$I$11="Registro Git","R",IF(TAREAS!$I$11="Despliegue documentado","D","L")),"")) | AA12: =IF(TAREAS!$I$11="Propuesta",IF(AND(AA$7>=TAREAS!$G$11,AA$7<=TAREAS!$H$11,CALENDARIO!$C$31=1),"P",""),IF(ISNUMBER(SEARCH(TEXT(AA$7,"yyyy-mm-dd"),TAREAS!$J$11)),IF(TAREAS!$I$11="Registro Git","R",IF(TAREAS!$I$11="Despliegue documentado","D","L")),"")) | AB12: =IF(TAREAS!$I$11="Propuesta",IF(AND(AB$7>=TAREAS!$G$11,AB$7<=TAREAS!$H$11,CALENDARIO!$C$32=1),"P",""),IF(ISNUMBER(SEARCH(TEXT(AB$7,"yyyy-mm-dd"),TAREAS!$J$11)),IF(TAREAS!$I$11="Registro Git","R",IF(TAREAS!$I$11="Despliegue documentado","D","L")),"")) | AC12: =IF(TAREAS!$I$11="Propuesta",IF(AND(AC$7>=TAREAS!$G$11,AC$7<=TAREAS!$H$11,CALENDARIO!$C$33=1),"P",""),IF(ISNUMBER(SEARCH(TEXT(AC$7,"yyyy-mm-dd"),TAREAS!$J$11)),IF(TAREAS!$I$11="Registro Git","R",IF(TAREAS!$I$11="Despliegue documentado","D","L")),"")) | AD12: =IF(TAREAS!$I$11="Propuesta",IF(AND(AD$7>=TAREAS!$G$11,AD$7<=TAREAS!$H$11,CALENDARIO!$C$34=1),"P",""),IF(ISNUMBER(SEARCH(TEXT(AD$7,"yyyy-mm-dd"),TAREAS!$J$11)),IF(TAREAS!$I$11="Registro Git","R",IF(TAREAS!$I$11="Despliegue documentado","D","L")),"")) | AE12: =IF(TAREAS!$I$11="Propuesta",IF(AND(AE$7>=TAREAS!$G$11,AE$7<=TAREAS!$H$11,CALENDARIO!$C$35=1),"P",""),IF(ISNUMBER(SEARCH(TEXT(AE$7,"yyyy-mm-dd"),TAREAS!$J$11)),IF(TAREAS!$I$11="Registro Git","R",IF(TAREAS!$I$11="Despliegue documentado","D","L")),"")) | AF12: =IF(TAREAS!$I$11="Propuesta",IF(AND(AF$7>=TAREAS!$G$11,AF$7<=TAREAS!$H$11,CALENDARIO!$C$36=1),"P",""),IF(ISNUMBER(SEARCH(TEXT(AF$7,"yyyy-mm-dd"),TAREAS!$J$11)),IF(TAREAS!$I$11="Registro Git","R",IF(TAREAS!$I$11="Despliegue documentado","D","L")),"")) | AG12: =IF(TAREAS!$I$11="Propuesta",IF(AND(AG$7>=TAREAS!$G$11,AG$7<=TAREAS!$H$11,CALENDARIO!$C$37=1),"P",""),IF(ISNUMBER(SEARCH(TEXT(AG$7,"yyyy-mm-dd"),TAREAS!$J$11)),IF(TAREAS!$I$11="Registro Git","R",IF(TAREAS!$I$11="Despliegue documentado","D","L")),"")) | AH12: =IF(TAREAS!$I$11="Propuesta",IF(AND(AH$7>=TAREAS!$G$11,AH$7<=TAREAS!$H$11,CALENDARIO!$C$38=1),"P",""),IF(ISNUMBER(SEARCH(TEXT(AH$7,"yyyy-mm-dd"),TAREAS!$J$11)),IF(TAREAS!$I$11="Registro Git","R",IF(TAREAS!$I$11="Despliegue documentado","D","L")),""))
A13: =TAREAS!C12 -> HU-G04 · Como colaborador, quiero entregar evidencias y conocer el cierre de mi jornada. | B13: =TAREAS!A12&" · "&TAREAS!D12 -> T-008 · Corrección de evidencias y comprobante de Facebook | C13: =TAREAS!F12 -> yeiserDev | D13: =COUNTIF(E13:AH13,"R")+COUNTIF(E13:AH13,"D")+COUNTIF(E13:AH13,"L")+COUNTIF(E13:AH13,"P") -> 1 | E13: =IF(TAREAS!$I$12="Propuesta",IF(AND(E$7>=TAREAS!$G$12,E$7<=TAREAS!$H$12,CALENDARIO!$C$9=1),"P",""),IF(ISNUMBER(SEARCH(TEXT(E$7,"yyyy-mm-dd"),TAREAS!$J$12)),IF(TAREAS!$I$12="Registro Git","R",IF(TAREAS!$I$12="Despliegue documentado","D","L")),"")) | F13: =IF(TAREAS!$I$12="Propuesta",IF(AND(F$7>=TAREAS!$G$12,F$7<=TAREAS!$H$12,CALENDARIO!$C$10=1),"P",""),IF(ISNUMBER(SEARCH(TEXT(F$7,"yyyy-mm-dd"),TAREAS!$J$12)),IF(TAREAS!$I$12="Registro Git","R",IF(TAREAS!$I$12="Despliegue documentado","D","L")),"")) | G13: =IF(TAREAS!$I$12="Propuesta",IF(AND(G$7>=TAREAS!$G$12,G$7<=TAREAS!$H$12,CALENDARIO!$C$11=1),"P",""),IF(ISNUMBER(SEARCH(TEXT(G$7,"yyyy-mm-dd"),TAREAS!$J$12)),IF(TAREAS!$I$12="Registro Git","R",IF(TAREAS!$I$12="Despliegue documentado","D","L")),"")) | H13: =IF(TAREAS!$I$12="Propuesta",IF(AND(H$7>=TAREAS!$G$12,H$7<=TAREAS!$H$12,CALENDARIO!$C$12=1),"P",""),IF(ISNUMBER(SEARCH(TEXT(H$7,"yyyy-mm-dd"),TAREAS!$J$12)),IF(TAREAS!$I$12="Registro Git","R",IF(TAREAS!$I$12="Despliegue documentado","D","L")),"")) | I13: =IF(TAREAS!$I$12="Propuesta",IF(AND(I$7>=TAREAS!$G$12,I$7<=TAREAS!$H$12,CALENDARIO!$C$13=1),"P",""),IF(ISNUMBER(SEARCH(TEXT(I$7,"yyyy-mm-dd"),TAREAS!$J$12)),IF(TAREAS!$I$12="Registro Git","R",IF(TAREAS!$I$12="Despliegue documentado","D","L")),"")) | J13: =IF(TAREAS!$I$12="Propuesta",IF(AND(J$7>=TAREAS!$G$12,J$7<=TAREAS!$H$12,CALENDARIO!$C$14=1),"P",""),IF(ISNUMBER(SEARCH(TEXT(J$7,"yyyy-mm-dd"),TAREAS!$J$12)),IF(TAREAS!$I$12="Registro Git","R",IF(TAREAS!$I$12="Despliegue documentado","D","L")),"")) | K13: =IF(TAREAS!$I$12="Propuesta",IF(AND(K$7>=TAREAS!$G$12,K$7<=TAREAS!$H$12,CALENDARIO!$C$15=1),"P",""),IF(ISNUMBER(SEARCH(TEXT(K$7,"yyyy-mm-dd"),TAREAS!$J$12)),IF(TAREAS!$I$12="Registro Git","R",IF(TAREAS!$I$12="Despliegue documentado","D","L")),"")) -> R | L13: =IF(TAREAS!$I$12="Propuesta",IF(AND(L$7>=TAREAS!$G$12,L$7<=TAREAS!$H$12,CALENDARIO!$C$16=1),"P",""),IF(ISNUMBER(SEARCH(TEXT(L$7,"yyyy-mm-dd"),TAREAS!$J$12)),IF(TAREAS!$I$12="Registro Git","R",IF(TAREAS!$I$12="Despliegue documentado","D","L")),"")) | M13: =IF(TAREAS!$I$12="Propuesta",IF(AND(M$7>=TAREAS!$G$12,M$7<=TAREAS!$H$12,CALENDARIO!$C$17=1),"P",""),IF(ISNUMBER(SEARCH(TEXT(M$7,"yyyy-mm-dd"),TAREAS!$J$12)),IF(TAREAS!$I$12="Registro Git","R",IF(TAREAS!$I$12="Despliegue documentado","D","L")),"")) | N13: =IF(TAREAS!$I$12="Propuesta",IF(AND(N$7>=TAREAS!$G$12,N$7<=TAREAS!$H$12,CALENDARIO!$C$18=1),"P",""),IF(ISNUMBER(SEARCH(TEXT(N$7,"yyyy-mm-dd"),TAREAS!$J$12)),IF(TAREAS!$I$12="Registro Git","R",IF(TAREAS!$I$12="Despliegue documentado","D","L")),"")) | O13: =IF(TAREAS!$I$12="Propuesta",IF(AND(O$7>=TAREAS!$G$12,O$7<=TAREAS!$H$12,CALENDARIO!$C$19=1),"P",""),IF(ISNUMBER(SEARCH(TEXT(O$7,"yyyy-mm-dd"),TAREAS!$J$12)),IF(TAREAS!$I$12="Registro Git","R",IF(TAREAS!$I$12="Despliegue documentado","D","L")),"")) | P13: =IF(TAREAS!$I$12="Propuesta",IF(AND(P$7>=TAREAS!$G$12,P$7<=TAREAS!$H$12,CALENDARIO!$C$20=1),"P",""),IF(ISNUMBER(SEARCH(TEXT(P$7,"yyyy-mm-dd"),TAREAS!$J$12)),IF(TAREAS!$I$12="Registro Git","R",IF(TAREAS!$I$12="Despliegue documentado","D","L")),"")) | Q13: =IF(TAREAS!$I$12="Propuesta",IF(AND(Q$7>=TAREAS!$G$12,Q$7<=TAREAS!$H$12,CALENDARIO!$C$21=1),"P",""),IF(ISNUMBER(SEARCH(TEXT(Q$7,"yyyy-mm-dd"),TAREAS!$J$12)),IF(TAREAS!$I$12="Registro Git","R",IF(TAREAS!$I$12="Despliegue documentado","D","L")),"")) | R13: =IF(TAREAS!$I$12="Propuesta",IF(AND(R$7>=TAREAS!$G$12,R$7<=TAREAS!$H$12,CALENDARIO!$C$22=1),"P",""),IF(ISNUMBER(SEARCH(TEXT(R$7,"yyyy-mm-dd"),TAREAS!$J$12)),IF(TAREAS!$I$12="Registro Git","R",IF(TAREAS!$I$12="Despliegue documentado","D","L")),"")) | S13: =IF(TAREAS!$I$12="Propuesta",IF(AND(S$7>=TAREAS!$G$12,S$7<=TAREAS!$H$12,CALENDARIO!$C$23=1),"P",""),IF(ISNUMBER(SEARCH(TEXT(S$7,"yyyy-mm-dd"),TAREAS!$J$12)),IF(TAREAS!$I$12="Registro Git","R",IF(TAREAS!$I$12="Despliegue documentado","D","L")),"")) | T13: =IF(TAREAS!$I$12="Propuesta",IF(AND(T$7>=TAREAS!$G$12,T$7<=TAREAS!$H$12,CALENDARIO!$C$24=1),"P",""),IF(ISNUMBER(SEARCH(TEXT(T$7,"yyyy-mm-dd"),TAREAS!$J$12)),IF(TAREAS!$I$12="Registro Git","R",IF(TAREAS!$I$12="Despliegue documentado","D","L")),"")) | U13: =IF(TAREAS!$I$12="Propuesta",IF(AND(U$7>=TAREAS!$G$12,U$7<=TAREAS!$H$12,CALENDARIO!$C$25=1),"P",""),IF(ISNUMBER(SEARCH(TEXT(U$7,"yyyy-mm-dd"),TAREAS!$J$12)),IF(TAREAS!$I$12="Registro Git","R",IF(TAREAS!$I$12="Despliegue documentado","D","L")),"")) | V13: =IF(TAREAS!$I$12="Propuesta",IF(AND(V$7>=TAREAS!$G$12,V$7<=TAREAS!$H$12,CALENDARIO!$C$26=1),"P",""),IF(ISNUMBER(SEARCH(TEXT(V$7,"yyyy-mm-dd"),TAREAS!$J$12)),IF(TAREAS!$I$12="Registro Git","R",IF(TAREAS!$I$12="Despliegue documentado","D","L")),"")) | W13: =IF(TAREAS!$I$12="Propuesta",IF(AND(W$7>=TAREAS!$G$12,W$7<=TAREAS!$H$12,CALENDARIO!$C$27=1),"P",""),IF(ISNUMBER(SEARCH(TEXT(W$7,"yyyy-mm-dd"),TAREAS!$J$12)),IF(TAREAS!$I$12="Registro Git","R",IF(TAREAS!$I$12="Despliegue documentado","D","L")),"")) | X13: =IF(TAREAS!$I$12="Propuesta",IF(AND(X$7>=TAREAS!$G$12,X$7<=TAREAS!$H$12,CALENDARIO!$C$28=1),"P",""),IF(ISNUMBER(SEARCH(TEXT(X$7,"yyyy-mm-dd"),TAREAS!$J$12)),IF(TAREAS!$I$12="Registro Git","R",IF(TAREAS!$I$12="Despliegue documentado","D","L")),"")) | Y13: =IF(TAREAS!$I$12="Propuesta",IF(AND(Y$7>=TAREAS!$G$12,Y$7<=TAREAS!$H$12,CALENDARIO!$C$29=1),"P",""),IF(ISNUMBER(SEARCH(TEXT(Y$7,"yyyy-mm-dd"),TAREAS!$J$12)),IF(TAREAS!$I$12="Registro Git","R",IF(TAREAS!$I$12="Despliegue documentado","D","L")),"")) | Z13: =IF(TAREAS!$I$12="Propuesta",IF(AND(Z$7>=TAREAS!$G$12,Z$7<=TAREAS!$H$12,CALENDARIO!$C$30=1),"P",""),IF(ISNUMBER(SEARCH(TEXT(Z$7,"yyyy-mm-dd"),TAREAS!$J$12)),IF(TAREAS!$I$12="Registro Git","R",IF(TAREAS!$I$12="Despliegue documentado","D","L")),"")) | AA13: =IF(TAREAS!$I$12="Propuesta",IF(AND(AA$7>=TAREAS!$G$12,AA$7<=TAREAS!$H$12,CALENDARIO!$C$31=1),"P",""),IF(ISNUMBER(SEARCH(TEXT(AA$7,"yyyy-mm-dd"),TAREAS!$J$12)),IF(TAREAS!$I$12="Registro Git","R",IF(TAREAS!$I$12="Despliegue documentado","D","L")),"")) | AB13: =IF(TAREAS!$I$12="Propuesta",IF(AND(AB$7>=TAREAS!$G$12,AB$7<=TAREAS!$H$12,CALENDARIO!$C$32=1),"P",""),IF(ISNUMBER(SEARCH(TEXT(AB$7,"yyyy-mm-dd"),TAREAS!$J$12)),IF(TAREAS!$I$12="Registro Git","R",IF(TAREAS!$I$12="Despliegue documentado","D","L")),"")) | AC13: =IF(TAREAS!$I$12="Propuesta",IF(AND(AC$7>=TAREAS!$G$12,AC$7<=TAREAS!$H$12,CALENDARIO!$C$33=1),"P",""),IF(ISNUMBER(SEARCH(TEXT(AC$7,"yyyy-mm-dd"),TAREAS!$J$12)),IF(TAREAS!$I$12="Registro Git","R",IF(TAREAS!$I$12="Despliegue documentado","D","L")),"")) | AD13: =IF(TAREAS!$I$12="Propuesta",IF(AND(AD$7>=TAREAS!$G$12,AD$7<=TAREAS!$H$12,CALENDARIO!$C$34=1),"P",""),IF(ISNUMBER(SEARCH(TEXT(AD$7,"yyyy-mm-dd"),TAREAS!$J$12)),IF(TAREAS!$I$12="Registro Git","R",IF(TAREAS!$I$12="Despliegue documentado","D","L")),"")) | AE13: =IF(TAREAS!$I$12="Propuesta",IF(AND(AE$7>=TAREAS!$G$12,AE$7<=TAREAS!$H$12,CALENDARIO!$C$35=1),"P",""),IF(ISNUMBER(SEARCH(TEXT(AE$7,"yyyy-mm-dd"),TAREAS!$J$12)),IF(TAREAS!$I$12="Registro Git","R",IF(TAREAS!$I$12="Despliegue documentado","D","L")),"")) | AF13: =IF(TAREAS!$I$12="Propuesta",IF(AND(AF$7>=TAREAS!$G$12,AF$7<=TAREAS!$H$12,CALENDARIO!$C$36=1),"P",""),IF(ISNUMBER(SEARCH(TEXT(AF$7,"yyyy-mm-dd"),TAREAS!$J$12)),IF(TAREAS!$I$12="Registro Git","R",IF(TAREAS!$I$12="Despliegue documentado","D","L")),"")) | AG13: =IF(TAREAS!$I$12="Propuesta",IF(AND(AG$7>=TAREAS!$G$12,AG$7<=TAREAS!$H$12,CALENDARIO!$C$37=1),"P",""),IF(ISNUMBER(SEARCH(TEXT(AG$7,"yyyy-mm-dd"),TAREAS!$J$12)),IF(TAREAS!$I$12="Registro Git","R",IF(TAREAS!$I$12="Despliegue documentado","D","L")),"")) | AH13: =IF(TAREAS!$I$12="Propuesta",IF(AND(AH$7>=TAREAS!$G$12,AH$7<=TAREAS!$H$12,CALENDARIO!$C$38=1),"P",""),IF(ISNUMBER(SEARCH(TEXT(AH$7,"yyyy-mm-dd"),TAREAS!$J$12)),IF(TAREAS!$I$12="Registro Git","R",IF(TAREAS!$I$12="Despliegue documentado","D","L")),""))
A14: =TAREAS!C13 -> HU-G05 · Como responsable, quiero asignar trabajo y supervisar el cumplimiento. | B14: =TAREAS!A13&" · "&TAREAS!D13 -> T-009 · Revisión, observaciones y notificaciones de evidencias | C14: =TAREAS!F13 -> yeiserDev | D14: =COUNTIF(E14:AH14,"R")+COUNTIF(E14:AH14,"D")+COUNTIF(E14:AH14,"L")+COUNTIF(E14:AH14,"P") -> 3 | E14: =IF(TAREAS!$I$13="Propuesta",IF(AND(E$7>=TAREAS!$G$13,E$7<=TAREAS!$H$13,CALENDARIO!$C$9=1),"P",""),IF(ISNUMBER(SEARCH(TEXT(E$7,"yyyy-mm-dd"),TAREAS!$J$13)),IF(TAREAS!$I$13="Registro Git","R",IF(TAREAS!$I$13="Despliegue documentado","D","L")),"")) | F14: =IF(TAREAS!$I$13="Propuesta",IF(AND(F$7>=TAREAS!$G$13,F$7<=TAREAS!$H$13,CALENDARIO!$C$10=1),"P",""),IF(ISNUMBER(SEARCH(TEXT(F$7,"yyyy-mm-dd"),TAREAS!$J$13)),IF(TAREAS!$I$13="Registro Git","R",IF(TAREAS!$I$13="Despliegue documentado","D","L")),"")) | G14: =IF(TAREAS!$I$13="Propuesta",IF(AND(G$7>=TAREAS!$G$13,G$7<=TAREAS!$H$13,CALENDARIO!$C$11=1),"P",""),IF(ISNUMBER(SEARCH(TEXT(G$7,"yyyy-mm-dd"),TAREAS!$J$13)),IF(TAREAS!$I$13="Registro Git","R",IF(TAREAS!$I$13="Despliegue documentado","D","L")),"")) | H14: =IF(TAREAS!$I$13="Propuesta",IF(AND(H$7>=TAREAS!$G$13,H$7<=TAREAS!$H$13,CALENDARIO!$C$12=1),"P",""),IF(ISNUMBER(SEARCH(TEXT(H$7,"yyyy-mm-dd"),TAREAS!$J$13)),IF(TAREAS!$I$13="Registro Git","R",IF(TAREAS!$I$13="Despliegue documentado","D","L")),"")) | I14: =IF(TAREAS!$I$13="Propuesta",IF(AND(I$7>=TAREAS!$G$13,I$7<=TAREAS!$H$13,CALENDARIO!$C$13=1),"P",""),IF(ISNUMBER(SEARCH(TEXT(I$7,"yyyy-mm-dd"),TAREAS!$J$13)),IF(TAREAS!$I$13="Registro Git","R",IF(TAREAS!$I$13="Despliegue documentado","D","L")),"")) | J14: =IF(TAREAS!$I$13="Propuesta",IF(AND(J$7>=TAREAS!$G$13,J$7<=TAREAS!$H$13,CALENDARIO!$C$14=1),"P",""),IF(ISNUMBER(SEARCH(TEXT(J$7,"yyyy-mm-dd"),TAREAS!$J$13)),IF(TAREAS!$I$13="Registro Git","R",IF(TAREAS!$I$13="Despliegue documentado","D","L")),"")) | K14: =IF(TAREAS!$I$13="Propuesta",IF(AND(K$7>=TAREAS!$G$13,K$7<=TAREAS!$H$13,CALENDARIO!$C$15=1),"P",""),IF(ISNUMBER(SEARCH(TEXT(K$7,"yyyy-mm-dd"),TAREAS!$J$13)),IF(TAREAS!$I$13="Registro Git","R",IF(TAREAS!$I$13="Despliegue documentado","D","L")),"")) -> R | L14: =IF(TAREAS!$I$13="Propuesta",IF(AND(L$7>=TAREAS!$G$13,L$7<=TAREAS!$H$13,CALENDARIO!$C$16=1),"P",""),IF(ISNUMBER(SEARCH(TEXT(L$7,"yyyy-mm-dd"),TAREAS!$J$13)),IF(TAREAS!$I$13="Registro Git","R",IF(TAREAS!$I$13="Despliegue documentado","D","L")),"")) -> R | M14: =IF(TAREAS!$I$13="Propuesta",IF(AND(M$7>=TAREAS!$G$13,M$7<=TAREAS!$H$13,CALENDARIO!$C$17=1),"P",""),IF(ISNUMBER(SEARCH(TEXT(M$7,"yyyy-mm-dd"),TAREAS!$J$13)),IF(TAREAS!$I$13="Registro Git","R",IF(TAREAS!$I$13="Despliegue documentado","D","L")),"")) -> R | N14: =IF(TAREAS!$I$13="Propuesta",IF(AND(N$7>=TAREAS!$G$13,N$7<=TAREAS!$H$13,CALENDARIO!$C$18=1),"P",""),IF(ISNUMBER(SEARCH(TEXT(N$7,"yyyy-mm-dd"),TAREAS!$J$13)),IF(TAREAS!$I$13="Registro Git","R",IF(TAREAS!$I$13="Despliegue documentado","D","L")),"")) | O14: =IF(TAREAS!$I$13="Propuesta",IF(AND(O$7>=TAREAS!$G$13,O$7<=TAREAS!$H$13,CALENDARIO!$C$19=1),"P",""),IF(ISNUMBER(SEARCH(TEXT(O$7,"yyyy-mm-dd"),TAREAS!$J$13)),IF(TAREAS!$I$13="Registro Git","R",IF(TAREAS!$I$13="Despliegue documentado","D","L")),"")) | P14: =IF(TAREAS!$I$13="Propuesta",IF(AND(P$7>=TAREAS!$G$13,P$7<=TAREAS!$H$13,CALENDARIO!$C$20=1),"P",""),IF(ISNUMBER(SEARCH(TEXT(P$7,"yyyy-mm-dd"),TAREAS!$J$13)),IF(TAREAS!$I$13="Registro Git","R",IF(TAREAS!$I$13="Despliegue documentado","D","L")),"")) | Q14: =IF(TAREAS!$I$13="Propuesta",IF(AND(Q$7>=TAREAS!$G$13,Q$7<=TAREAS!$H$13,CALENDARIO!$C$21=1),"P",""),IF(ISNUMBER(SEARCH(TEXT(Q$7,"yyyy-mm-dd"),TAREAS!$J$13)),IF(TAREAS!$I$13="Registro Git","R",IF(TAREAS!$I$13="Despliegue documentado","D","L")),"")) | R14: =IF(TAREAS!$I$13="Propuesta",IF(AND(R$7>=TAREAS!$G$13,R$7<=TAREAS!$H$13,CALENDARIO!$C$22=1),"P",""),IF(ISNUMBER(SEARCH(TEXT(R$7,"yyyy-mm-dd"),TAREAS!$J$13)),IF(TAREAS!$I$13="Registro Git","R",IF(TAREAS!$I$13="Despliegue documentado","D","L")),"")) | S14: =IF(TAREAS!$I$13="Propuesta",IF(AND(S$7>=TAREAS!$G$13,S$7<=TAREAS!$H$13,CALENDARIO!$C$23=1),"P",""),IF(ISNUMBER(SEARCH(TEXT(S$7,"yyyy-mm-dd"),TAREAS!$J$13)),IF(TAREAS!$I$13="Registro Git","R",IF(TAREAS!$I$13="Despliegue documentado","D","L")),"")) | T14: =IF(TAREAS!$I$13="Propuesta",IF(AND(T$7>=TAREAS!$G$13,T$7<=TAREAS!$H$13,CALENDARIO!$C$24=1),"P",""),IF(ISNUMBER(SEARCH(TEXT(T$7,"yyyy-mm-dd"),TAREAS!$J$13)),IF(TAREAS!$I$13="Registro Git","R",IF(TAREAS!$I$13="Despliegue documentado","D","L")),"")) | U14: =IF(TAREAS!$I$13="Propuesta",IF(AND(U$7>=TAREAS!$G$13,U$7<=TAREAS!$H$13,CALENDARIO!$C$25=1),"P",""),IF(ISNUMBER(SEARCH(TEXT(U$7,"yyyy-mm-dd"),TAREAS!$J$13)),IF(TAREAS!$I$13="Registro Git","R",IF(TAREAS!$I$13="Despliegue documentado","D","L")),"")) | V14: =IF(TAREAS!$I$13="Propuesta",IF(AND(V$7>=TAREAS!$G$13,V$7<=TAREAS!$H$13,CALENDARIO!$C$26=1),"P",""),IF(ISNUMBER(SEARCH(TEXT(V$7,"yyyy-mm-dd"),TAREAS!$J$13)),IF(TAREAS!$I$13="Registro Git","R",IF(TAREAS!$I$13="Despliegue documentado","D","L")),"")) | W14: =IF(TAREAS!$I$13="Propuesta",IF(AND(W$7>=TAREAS!$G$13,W$7<=TAREAS!$H$13,CALENDARIO!$C$27=1),"P",""),IF(ISNUMBER(SEARCH(TEXT(W$7,"yyyy-mm-dd"),TAREAS!$J$13)),IF(TAREAS!$I$13="Registro Git","R",IF(TAREAS!$I$13="Despliegue documentado","D","L")),"")) | X14: =IF(TAREAS!$I$13="Propuesta",IF(AND(X$7>=TAREAS!$G$13,X$7<=TAREAS!$H$13,CALENDARIO!$C$28=1),"P",""),IF(ISNUMBER(SEARCH(TEXT(X$7,"yyyy-mm-dd"),TAREAS!$J$13)),IF(TAREAS!$I$13="Registro Git","R",IF(TAREAS!$I$13="Despliegue documentado","D","L")),"")) | Y14: =IF(TAREAS!$I$13="Propuesta",IF(AND(Y$7>=TAREAS!$G$13,Y$7<=TAREAS!$H$13,CALENDARIO!$C$29=1),"P",""),IF(ISNUMBER(SEARCH(TEXT(Y$7,"yyyy-mm-dd"),TAREAS!$J$13)),IF(TAREAS!$I$13="Registro Git","R",IF(TAREAS!$I$13="Despliegue documentado","D","L")),"")) | Z14: =IF(TAREAS!$I$13="Propuesta",IF(AND(Z$7>=TAREAS!$G$13,Z$7<=TAREAS!$H$13,CALENDARIO!$C$30=1),"P",""),IF(ISNUMBER(SEARCH(TEXT(Z$7,"yyyy-mm-dd"),TAREAS!$J$13)),IF(TAREAS!$I$13="Registro Git","R",IF(TAREAS!$I$13="Despliegue documentado","D","L")),"")) | AA14: =IF(TAREAS!$I$13="Propuesta",IF(AND(AA$7>=TAREAS!$G$13,AA$7<=TAREAS!$H$13,CALENDARIO!$C$31=1),"P",""),IF(ISNUMBER(SEARCH(TEXT(AA$7,"yyyy-mm-dd"),TAREAS!$J$13)),IF(TAREAS!$I$13="Registro Git","R",IF(TAREAS!$I$13="Despliegue documentado","D","L")),"")) | AB14: =IF(TAREAS!$I$13="Propuesta",IF(AND(AB$7>=TAREAS!$G$13,AB$7<=TAREAS!$H$13,CALENDARIO!$C$32=1),"P",""),IF(ISNUMBER(SEARCH(TEXT(AB$7,"yyyy-mm-dd"),TAREAS!$J$13)),IF(TAREAS!$I$13="Registro Git","R",IF(TAREAS!$I$13="Despliegue documentado","D","L")),"")) | AC14: =IF(TAREAS!$I$13="Propuesta",IF(AND(AC$7>=TAREAS!$G$13,AC$7<=TAREAS!$H$13,CALENDARIO!$C$33=1),"P",""),IF(ISNUMBER(SEARCH(TEXT(AC$7,"yyyy-mm-dd"),TAREAS!$J$13)),IF(TAREAS!$I$13="Registro Git","R",IF(TAREAS!$I$13="Despliegue documentado","D","L")),"")) | AD14: =IF(TAREAS!$I$13="Propuesta",IF(AND(AD$7>=TAREAS!$G$13,AD$7<=TAREAS!$H$13,CALENDARIO!$C$34=1),"P",""),IF(ISNUMBER(SEARCH(TEXT(AD$7,"yyyy-mm-dd"),TAREAS!$J$13)),IF(TAREAS!$I$13="Registro Git","R",IF(TAREAS!$I$13="Despliegue documentado","D","L")),"")) | AE14: =IF(TAREAS!$I$13="Propuesta",IF(AND(AE$7>=TAREAS!$G$13,AE$7<=TAREAS!$H$13,CALENDARIO!$C$35=1),"P",""),IF(ISNUMBER(SEARCH(TEXT(AE$7,"yyyy-mm-dd"),TAREAS!$J$13)),IF(TAREAS!$I$13="Registro Git","R",IF(TAREAS!$I$13="Despliegue documentado","D","L")),"")) | AF14: =IF(TAREAS!$I$13="Propuesta",IF(AND(AF$7>=TAREAS!$G$13,AF$7<=TAREAS!$H$13,CALENDARIO!$C$36=1),"P",""),IF(ISNUMBER(SEARCH(TEXT(AF$7,"yyyy-mm-dd"),TAREAS!$J$13)),IF(TAREAS!$I$13="Registro Git","R",IF(TAREAS!$I$13="Despliegue documentado","D","L")),"")) | AG14: =IF(TAREAS!$I$13="Propuesta",IF(AND(AG$7>=TAREAS!$G$13,AG$7<=TAREAS!$H$13,CALENDARIO!$C$37=1),"P",""),IF(ISNUMBER(SEARCH(TEXT(AG$7,"yyyy-mm-dd"),TAREAS!$J$13)),IF(TAREAS!$I$13="Registro Git","R",IF(TAREAS!$I$13="Despliegue documentado","D","L")),"")) | AH14: =IF(TAREAS!$I$13="Propuesta",IF(AND(AH$7>=TAREAS!$G$13,AH$7<=TAREAS!$H$13,CALENDARIO!$C$38=1),"P",""),IF(ISNUMBER(SEARCH(TEXT(AH$7,"yyyy-mm-dd"),TAREAS!$J$13)),IF(TAREAS!$I$13="Registro Git","R",IF(TAREAS!$I$13="Despliegue documentado","D","L")),""))
